# Setting up the environment

```ocaml
# #require "eio_main";;
```

```ocaml
open Eio.Std

let run fn =
  Eio_main.run @@ fun _ ->
  traceln "%s" (fn ())
```

# Fibre.first

First finishes, second is cancelled:

```ocaml
# run @@ fun () ->
  let p, r = Promise.create () in
  Fibre.first
    (fun () -> "a")
    (fun () -> Promise.await p);;
+a
- : unit = ()
```

Second finishes, first is cancelled:

```ocaml
# run @@ fun () ->
  let p, r = Promise.create () in
  Fibre.first
    (fun () -> Promise.await p)
    (fun () -> "b");;
+b
- : unit = ()
```

If both succeed, we pick the first one:

```ocaml
# run @@ fun () ->
  Fibre.first
    (fun () -> "a")
    (fun () -> "b");;
+a
- : unit = ()
```

One crashes - report it:

```ocaml
# run @@ fun () ->
  Fibre.first
    (fun () -> "a")
    (fun () -> failwith "b crashed");;
Exception: Failure "b crashed".
```

```ocaml
# run @@ fun () ->
  Fibre.first
    (fun () -> failwith "a crashed")
    (fun () -> "b");;
Exception: Failure "a crashed".
```

Both crash - report both:

```ocaml
# run @@ fun () ->
  Fibre.first
    (fun () -> failwith "a crashed")
    (fun () -> failwith "b crashed");;
Exception: Multiple exceptions:
Failure("a crashed")
and
Failure("b crashed")
```

Cancelled before it can crash:

```ocaml
# run @@ fun () ->
  Fibre.first
    (fun () -> "a")
    (fun () -> Fibre.yield (); failwith "b crashed");;
+a
- : unit = ()
```

One claims to be cancelled (for some reason other than the other fibre finishing):

```ocaml
# run @@ fun () ->
  Fibre.first
    (fun () -> raise (Eio.Cancel.Cancelled (Failure "cancel-a")))
    (fun () -> "b");;
Exception: Cancelled: Failure("cancel-a")
```

```ocaml
# run @@ fun () ->
  Fibre.first
    (fun () -> Fibre.yield (); "a")
    (fun () -> raise (Eio.Cancel.Cancelled (Failure "cancel-b")));;
Exception: Cancelled: Failure("cancel-b")
```

Cancelled from parent:

```ocaml
# run @@ fun () ->
  let p, r = Promise.create () in
  Fibre.both
    (fun () ->
      failwith @@ Fibre.first
        (fun () -> Promise.await p)
        (fun () -> Promise.await p)
    )
    (fun () -> failwith "Parent cancel");
  "not-reached";;
Exception: Failure "Parent cancel".
```

Cancelled from parent while already cancelling:

```ocaml
# run @@ fun () ->
  Fibre.both
    (fun () ->
      let _ = Fibre.first
        (fun () -> "a")
        (fun () -> Fibre.yield (); failwith "cancel-b")
      in
      traceln "Parent cancel failed"
    )
    (fun () -> traceln "Cancelling parent"; failwith "Parent cancel");
  "not-reached";;
+Cancelling parent
Exception: Failure "Parent cancel".
```

Cancelling in a sub-switch. We see the exception as `Cancelled Exit` when we're being asked to cancel,
but just as plain `Exit` after we leave the context in which the cancellation started:

```ocaml
# run @@ fun () ->
  let p, r = Promise.create () in
  Fibre.both
    (fun () ->
      try
        Switch.run (fun _ ->
          try Promise.await p
          with ex -> traceln "Nested exception: %a" Fmt.exn ex; raise ex
        )
      with ex -> traceln "Parent exception: %a" Fmt.exn ex; raise ex
    )
    (fun () -> raise Exit);
  failwith "not-reached";;
+Nested exception: Cancelled: Stdlib.Exit
+Parent exception: Cancelled: Stdlib.Exit
Exception: Stdlib.Exit.
```

# Fibre.pair

```ocaml
# run @@ fun () ->
  let x, y = Fibre.pair (fun () -> "a") (fun () -> "b") in
  x ^ y;;
+ab
- : unit = ()
```

# Fibre.all

```ocaml
# run @@ fun () ->
  Fibre.all [];
  Fibre.all (List.init 3 (fun x () -> traceln "fibre %d" x));
  "done";;
+fibre 0
+fibre 1
+fibre 2
+done
- : unit = ()
```

# Fibre.any

```ocaml
# run @@ fun () ->
  string_of_int @@
  Fibre.any (List.init 3 (fun x () -> traceln "%d" x; Fibre.yield (); x));;
+0
+1
+2
+0
- : unit = ()
```

# Fibre.await_cancel

```ocaml
# run @@ fun () ->
  Fibre.both
    (fun () ->
       try Fibre.await_cancel ()
       with Eio.Cancel.Cancelled _ as ex ->
         traceln "Caught: %a" Fmt.exn ex;
         raise ex
    )
    (fun () -> failwith "simulated error");
  "not reached";;
+Caught: Cancelled: Failure("simulated error")
Exception: Failure "simulated error".
```

# Fibre.fork

`Fibre.fork_promise ~sw` inherits the cancellation context from `sw`, not from the current fibre:

```ocaml
# run @@ fun () ->
  let switch = ref None in
  Fibre.both
    (fun () ->
       Switch.run @@ fun sw ->
       switch := Some sw;
       Fibre.await_cancel ()
    )
    (fun () ->
      let sw = Option.get !switch in
      Eio.Cancel.protect @@ fun () ->
      let child = Fibre.fork_promise ~sw (fun () ->
         traceln "Forked child";
         Fibre.await_cancel ()
      ) in
      Switch.fail sw Exit;
      Promise.await_exn child
    );
  "not reached";;
+Forked child
Exception: Stdlib.Exit.
```

# Scheduling order

Forking runs the child first, and puts the calling fibre at the head of the run-queue.

```ocaml
# run @@ fun () ->
  Switch.run @@ fun sw ->
  Fibre.fork ~sw (fun () -> traceln "1st child runs"; Fibre.yield (); traceln "Queued work");
  Fibre.fork ~sw (fun () -> traceln "2nd child runs immediately");
  traceln "Caller runs before queued work";
  "ok";;
+1st child runs
+2nd child runs immediately
+Caller runs before queued work
+Queued work
+ok
- : unit = ()
```

Same with `both`:

```ocaml
# run @@ fun () ->
  Switch.run @@ fun sw ->
  Fibre.fork ~sw (fun () -> traceln "Enqueuing work for later"; Fibre.yield (); traceln "Queued work");
  Fibre.both
    (fun () -> traceln "1st branch")
    (fun () -> traceln "2nd branch");
  "ok";;
+Enqueuing work for later
+1st branch
+2nd branch
+Queued work
+ok
- : unit = ()
```

Same with `first`:

```ocaml
# run @@ fun () ->
  Switch.run @@ fun sw ->
  Fibre.fork ~sw (fun () -> traceln "Enqueuing work for later"; Fibre.yield (); traceln "Queued work");
  Fibre.first
    (fun () -> traceln "1st branch")
    (fun () -> traceln "2nd branch");
  "ok";;
+Enqueuing work for later
+1st branch
+2nd branch
+Queued work
+ok
- : unit = ()
```

# fork_on_accept

We can attach resources to the switch in the accept function,
and they get released when the child fibre finishes.

```ocaml
let test_fork_on_accept ?(reraise=false) ?(cancel=false) ?(in_accept=ignore) ?(in_handler=ignore) sw =
  let on_handler_error =
    if reraise then raise
    else (fun ex -> traceln "on_handler_error: %a" Fmt.exn ex; Fibre.check ())
  in
  Fibre.both (fun () ->
    Fibre.fork_on_accept ~sw ~on_handler_error
      (fun sw ->
         traceln "Got connection";
         Switch.on_release sw (fun () -> traceln "Releasing connection"; Fibre.check ());
         in_accept sw;
         1
      )
      (fun sw x ->
         traceln "Run handler with %d" x;
         Fibre.yield ();
         in_handler sw;
         traceln "Handler done"
      );
    )
    (fun () -> if cancel then failwith "Simulated failure");
  traceln "Main fibre resumes";
  "Main fibre result"
```

The success case:

```ocaml
# run @@ fun () ->
  Switch.run test_fork_on_accept;;
+Got connection
+Run handler with 1
+Main fibre resumes
+Handler done
+Releasing connection
+Main fibre result
- : unit = ()
```

The accept function fails:

```ocaml
# run @@ fun () ->
  Switch.run @@ test_fork_on_accept ~in_accept:(fun _ -> failwith "Accept failure");;
+Got connection
+Releasing connection
Exception: Failure "Accept failure".
```

The handler function fails:

```ocaml
# run @@ fun () ->
  Switch.run @@ test_fork_on_accept ~in_handler:(fun _ -> failwith "Handler fails");;
+Got connection
+Run handler with 1
+Main fibre resumes
+Releasing connection
+on_handler_error: Failure("Handler fails")
+Main fibre result
- : unit = ()
```

Turning off the child switch in the accept function. We treat this as the handler being cancelled:

```ocaml
# run @@ fun () ->
  Switch.run @@ test_fork_on_accept ~in_accept:(fun sw -> Switch.fail sw (Failure "Accept turn-off"));;
+Got connection
+Releasing connection
+on_handler_error: Failure("Accept turn-off")
+Main fibre resumes
+Main fibre result
- : unit = ()
```

Propagating handling errors to the parent:

```ocaml
# run @@ fun () ->
  Switch.run @@ test_fork_on_accept ~in_handler:(fun _  -> failwith "Handler fails") ~reraise:true;;
+Got connection
+Run handler with 1
+Main fibre resumes
+Releasing connection
Exception: Failure "Handler fails".
```

Cancelling while in accept:

```ocaml
# run @@ fun () ->
  Switch.run @@ test_fork_on_accept ~in_accept:(fun _  -> Fibre.await_cancel ()) ~cancel:true;;
+Got connection
+Releasing connection
Exception: Failure "Simulated failure".
```

Cancelling while in handler. `on_hander_error` is not called for cancellations:

```ocaml
# run @@ fun () ->
  Switch.run @@ test_fork_on_accept ~in_handler:(fun _  -> Fibre.await_cancel ()) ~cancel:true;;
+Got connection
+Run handler with 1
+Releasing connection
Exception: Failure "Simulated failure".
```

Parent switch turned off. The main error is reported by the owner of the background thread,
with `fork_on_accept` just getting a `Cancelled` exception. The background switch can't exit
until the connection is released.

```ocaml
# run @@ fun () ->
  Switch.run @@ fun sw ->
  let bg_switch = ref None in
  Fibre.fork_sub ~sw ~on_error:(traceln "Background thread failed: %a" Fmt.exn) (fun sw ->
     bg_switch := Some sw; Fibre.await_cancel ()
  );
  let bg_switch = Option.get !bg_switch in
  test_fork_on_accept bg_switch
    ~in_accept:(fun _  ->
       Switch.fail bg_switch (Failure "Background switch turned off");
       Fibre.yield ()
    );;
+Got connection
+Releasing connection
+Background thread failed: Failure("Background switch turned off")
Exception: Cancelled: Failure("Background switch turned off")
```

The child outlives the forking context. The error handler runs in `bg_switch`, so it still works:

```ocaml
# run @@ fun () ->
  Switch.run @@ fun sw ->
  let bg_switch = ref None in
  Fibre.fork_sub ~sw ~on_error:(traceln "Background thread failed: %a" Fmt.exn) (fun sw ->
     bg_switch := Some sw; Fibre.yield ()
  );
  let bg_switch = Option.get !bg_switch in
  let x = Switch.run (fun _ ->
     test_fork_on_accept bg_switch
       ~in_handler:(fun _ ->
          Fibre.yield ();
          failwith "Simulated error"
       )
  ) in
  traceln "Main switch done";
  x
  ;;
+Got connection
+Run handler with 1
+Main fibre resumes
+Main switch done
+Releasing connection
+on_handler_error: Failure("Simulated error")
+Main fibre result
- : unit = ()
```
